package chap14_exception;

public class _03_throws {

	public static void main(String[] args) {
		// TODO Auto-generated method stub
		int[] arr = {1, 2, 3, 4};
		try {
			//throws로 예외처리된 메소드를 호출할 때는
			//예외가 발생할 수 있는 확률이 있기 때문에
			//try~catch로 묶어서 처리를 해야한다.
			getException(arr);
		} catch(Exception e) {
			System.out.println(e.getMessage());
		}
	}
	
	public static void getException(int[] intArr) 
							throws ArrayIndexOutOfBoundsException {
		for(int i = 0; i < 10; i++) {
			System.out.println(intArr[i]);
		}
	}
}
